2025-03-05 10:16:00,078 - INFO - ===== 应用程序启动 =====
2025-03-05 10:16:00,078 - INFO - 日志文件: logs\log_20250305_101600.txt
2025-03-05 10:16:24,077 - INFO - 开始执行脚本: code\1.1.py
2025-03-05 10:16:24,127 - ERROR - [错误] Traceback (most recent call last):
2025-03-05 10:16:24,127 - ERROR - [错误]   File "C:\Users\Administrator.DESKTOP-1B3PH7R\Desktop\测试\code\1.1.py", line 10, in <module>
2025-03-05 10:16:24,127 - ERROR - [错误]     raise Exception("该脚本在2025年2月25日之后无法使用。")
2025-03-05 10:16:24,138 - ERROR - [错误] Exception: 该脚本在2025年2月25日之后无法使用。
2025-03-05 10:16:24,157 - WARNING - 脚本 code\1.1.py 执行结束，但返回代码非零 (返回代码: 1)
2025-03-05 10:16:33,811 - INFO - 开始执行脚本: code\1.1.py
2025-03-05 10:16:33,861 - ERROR - [错误] Traceback (most recent call last):
2025-03-05 10:16:33,861 - ERROR - [错误]   File "C:\Users\Administrator.DESKTOP-1B3PH7R\Desktop\测试\code\1.1.py", line 10, in <module>
2025-03-05 10:16:33,861 - ERROR - [错误]     raise Exception("该脚本在2025年2月25日之后无法使用。")
2025-03-05 10:16:33,861 - ERROR - [错误] Exception: 该脚本在2025年2月25日之后无法使用。
2025-03-05 10:16:33,874 - WARNING - 脚本 code\1.1.py 执行结束，但返回代码非零 (返回代码: 1)
2025-03-05 10:17:28,962 - INFO - 开始执行脚本: code\1.1.py
2025-03-05 10:17:29,015 - ERROR - [错误] Traceback (most recent call last):
2025-03-05 10:17:29,015 - ERROR - [错误]   File "C:\Users\Administrator.DESKTOP-1B3PH7R\Desktop\测试\code\1.1.py", line 10, in <module>
2025-03-05 10:17:29,015 - ERROR - [错误]     raise Exception("该脚本在2025年2月25日之后无法使用。")
2025-03-05 10:17:29,025 - ERROR - [错误] Exception: 该脚本在2025年2月25日之后无法使用。
2025-03-05 10:17:29,031 - WARNING - 脚本 code\1.1.py 执行结束，但返回代码非零 (返回代码: 1)
